<?xml version="1.0" ?>
<sdf version="1.5">
  <model name="pioneer2dx">
  <link name="base_link"/>
    <joint name="base_joint" type="fixed">
      <parent>base_link</parent>
      <child>chassis</child>
    </joint>
    <link name="chassis">
      <pose>0 0 0.16 0 0 0</pose>
      <inertial>
        <mass>5.67</mass>
        <inertia>
          <ixx>0.07</ixx>
          <iyy>0.08</iyy>
          <izz>0.10</izz>
          <ixy>0</ixy>
          <ixz>0</ixz>
          <iyz>0</iyz>
        </inertia>
      </inertial>
      <collision name="collision">
        <geometry>
          <box>
            <size>0.445 0.277 0.17</size>
          </box>
        </geometry>
      </collision>
      <collision name="castor_collision">
        <pose>-0.200 0 -0.12 0 0 0</pose>
        <geometry>
          <sphere>
            <radius>0.04</radius>
          </sphere>
        </geometry>
        <surface>
          <friction>
            <ode>
              <mu>0</mu>
              <mu2>0</mu2>
              <slip1>1.0</slip1>
              <slip2>1.0</slip2>
            </ode>
          </friction>
        </surface>
      </collision>
      <visual name="visual">
        <pose>0 0 0.04 0 0 0</pose>
        <geometry>
          <mesh>
            <uri>model://pioneer2dx/meshes/chassis.dae</uri>
          </mesh>
        </geometry>
      </visual>
      <visual name="castor_visual">
        <pose>-0.200 0 -0.12 0 0 0</pose>
        <geometry>
          <sphere>
            <radius>0.04</radius>
          </sphere>
        </geometry>
        <material>
          <script>
            <uri>file://media/materials/scripts/gazebo.material</uri>
            <name>Gazebo/FlatBlack</name>
          </script>
        </material>
      </visual>
      <sensor name="camera_sensor" type="camera">
        <pose>0.2 0 0.15 0 0 0</pose> <always_on>1</always_on>
        <update_rate>30</update_rate>
        <visualize>true</visualize>
        <camera>
          <horizontal_fov>1.396</horizontal_fov>
          <image>
            <width>640</width>
            <height>480</height>
            <format>R8G8B8</format>
          </image>
          <clip>
            <near>0.1</near>
            <far>100</far>
          </clip>
        </camera>
        <plugin name="gazebo_ros_camera" filename="libgazebo_ros_camera.so">
          <always_on>true</always_on>
          <update_rate>30</update_rate>
          <camera_name>camera</camera_name>
          <image_topic_name>image_raw</image_topic_name>
          <camera_info_topic_name>camera_info</camera_info_topic_name>
          <frame_name>camera_link</frame_name>
        </plugin>
      </sensor>
      <sensor name="lidar_sensor" type="ray">
        <pose>0.2 0 0.2 0 0 0</pose> <visualize>true</visualize>
        <update_rate>15.0</update_rate>
        <ray>
          <scan>
            <horizontal>
              <samples>360</samples>
              <resolution>1</resolution>
              <min_angle>-3.1416</min_angle>  <max_angle>3.1416</max_angle>   </horizontal>
          </scan>
          <range>
            <min>0.12</min>
            <max>4.0</max>
            <resolution>0.01</resolution>
          </range>
          <noise>
            <type>gaussian</type>
            <mean>0.0</mean>
            <stddev>0.05</stddev>
          </noise>
        </ray>

        <plugin name="gazebo_ros_laser" filename="libgazebo_ros_ray_sensor.so">
          <ros>
            <namespace>/</namespace>
            <remapping>~/out:=/scan</remapping>
          </ros>
          <frame_name>lidar_link</frame_name>
          <topic>scan</topic>
          <output_type>sensor_msgs/LaserScan</output_type>
        </plugin>
      </sensor>
    </link>
    <!-- IMU Link -->
    <link name="imu_link">
      <pose>0 0 0.2 0 0 0</pose>
      <inertial>
        <mass>0.1</mass>
        <inertia>
          <ixx>0.0001</ixx>
          <iyy>0.0001</iyy>
          <izz>0.0001</izz>
          <ixy>0</ixy>
          <ixz>0</ixz>
          <iyz>0</iyz>
        </inertia>
      </inertial>

      <sensor name="imu_sensor" type="imu">
        <pose>0 0 0 0 0 0</pose>
        <update_rate>10.0</update_rate>
        <always_on>true</always_on>
        <visualize>false</visualize>
        <imu>
          <angular_velocity>
            <x>true</x>
            <y>true</y>
            <z>true</z>
          </angular_velocity>
          <linear_acceleration>
            <x>true</x>
            <y>true</y>
            <z>true</z>
          </linear_acceleration>
          <orientation>
            <x>true</x>
            <y>true</y>
            <z>true</z>
          </orientation>
          <angular_velocity_covariance>0.0025 0 0 0 0.0025 0 0 0 0.0025</angular_velocity_covariance>
          <linear_acceleration_covariance>0.04 0 0 0 0.04 0 0 0 0.04</linear_acceleration_covariance>
          <orientation_covariance>0.02 0 0 0 0.02 0 0 0 0.02</orientation_covariance>
        </imu>
        <plugin name="gazebo_ros_imu_sensor" filename="libgazebo_ros_imu_sensor.so">
          <ros>
            <remapping>~/out:=/imu/data</remapping>
          </ros>
          <frame_name>imu_link</frame_name>
          <gaussian_noise>0.01</gaussian_noise>
        </plugin>
</sensor>
    </link>
    <joint name="imu_fixed_joint" type="fixed">
      <parent>base_link</parent>
      <child>imu_link</child>
      <pose>0 0 0 0 0 0</pose>
    </joint>
    <!-- Last added-->
    <link name="right_wheel">
      <pose>0.1 -.17 0.11 0 1.5707 1.5707</pose>
      <inertial>
        <mass>1.5</mass>
        <inertia>
          <ixx>0.0051</ixx>
          <iyy>0.0051</iyy>
          <izz>0.0090</izz>
          <ixy>0</ixy>
          <ixz>0</ixz>
          <iyz>0</iyz>
        </inertia>
      </inertial>
      <collision name="collision">
        <geometry>
          <cylinder>
            <radius>0.11</radius>
            <length>0.05</length>
          </cylinder>
        </geometry>
        <surface>
          <friction>
            <ode>
              <mu>100000.0</mu>
              <mu2>100000.0</mu2>
              <slip1>0.0</slip1>
              <slip2>0.0</slip2>
            </ode>
          </friction>
        </surface>
      </collision>
      <visual name="visual">
        <geometry>
          <cylinder>
            <radius>0.11</radius>
            <length>0.05</length>
          </cylinder>
        </geometry>
        <material>
          <script>
            <uri>file://media/materials/scripts/gazebo.material</uri>
            <name>Gazebo/FlatBlack</name>
          </script>
        </material>
      </visual>
    </link>
    <link name="left_wheel">
      <pose>0.1 .17 0.11 0 1.5707 1.5707</pose>
      <inertial>
        <mass>1.5</mass>
        <inertia>
          <ixx>0.0051</ixx>
          <iyy>0.0051</iyy>
          <izz>0.0090</izz>
          <ixy>0</ixy>
          <ixz>0</ixz>
          <iyz>0</iyz>
        </inertia>
      </inertial>
      <collision name="collision">
        <geometry>
          <cylinder>
            <radius>0.11</radius>
            <length>0.05</length>
          </cylinder>
        </geometry>
        <surface>
          <friction>
            <ode>
              <mu>100000.0</mu>
              <mu2>100000.0</mu2>
              <slip1>0.0</slip1>
              <slip2>0.0</slip2>
            </ode>
          </friction>
        </surface>
      </collision>
      <visual name="visual">
        <geometry>
          <cylinder>
            <radius>0.11</radius>
            <length>0.05</length>
          </cylinder>
        </geometry>
        <material>
          <script>
            <uri>file://media/materials/scripts/gazebo.material</uri>
            <name>Gazebo/FlatBlack</name>
          </script>
        </material>
      </visual>
    </link>
    <joint type="revolute" name="left_wheel_hinge">
      <pose>0 0 -0.03 0 0 0</pose>
      <child>left_wheel</child>
      <parent>chassis</parent>
      <axis>
        <xyz>0 1 0</xyz>
        <use_parent_model_frame>true</use_parent_model_frame>
      </axis>
    </joint>
    <joint type="revolute" name="right_wheel_hinge">
      <pose>0 0 0.03 0 0 0</pose>
      <child>right_wheel</child>
      <parent>chassis</parent>
      <axis>
        <xyz>0 1 0</xyz>
        <use_parent_model_frame>true</use_parent_model_frame>
      </axis>
    </joint>
    <plugin name="pioneer2dx_diff_drive" filename="libgazebo_ros_diff_drive.so">
      <ros>
        <remapping>cmd_vel:=/cmd_vel</remapping>
      </ros>
      <left_joint>left_wheel_hinge</left_joint>
      <right_joint>right_wheel_hinge</right_joint>
      <wheel_separation>0.34</wheel_separation>
      <wheel_diameter>0.22</wheel_diameter>
      <publish_odom>true</publish_odom>
      <publish_odom_tf>true</publish_odom_tf> <odometry_frame>odom</odometry_frame>
      <robot_base_frame>base_link</robot_base_frame>
      <update_rate>50</update_rate>
    </plugin>
    <plugin name="joint_state_publisher" filename="libgazebo_ros_joint_state_publisher.so">
      <ros>
        <remapping>joint_states:=joint_states</remapping>
      </ros>
      <joint_name>left_wheel_hinge</joint_name>
      <joint_name>right_wheel_hinge</joint_name>
    </plugin>
  </model>
</sdf>